Workbook

Sheet README
A1: FRED Graph Observations
A2: Federal Reserve Economic Data, Federal Reserve Bank of St. Louis
A3: Link: https://fred.stlouisfed.org
A4: Help: https://fredhelp.stlouisfed.org
A5: This data may be copyrighted. Please refer to the Terms of Use: https://fred.stlouisfed.org/legal#fred-terms-faq
A6: File Created: 2026-02-20 5:27 am CST
A8: DCOILWTICO | B8: Crude Oil Prices: West Texas Intermediate (WTI) - Cushing, Oklahoma, Dollars per Barrel, Daily, Not Seasonally Adjusted | C8: Data Updated: 2026-02-19

Sheet Daily
A1: observation_date | B1: DCOILWTICO
A2: 44244 | B2: 61.09
A3: 44245 | B3: 60.4
A4: 44246 | B4: 59.12
A5: 44249 | B5: 61.67
A6: 44250 | B6: 61.66
A7: 44251 | B7: 63.21
A8: 44252 | B8: 63.43
A9: 44253 | B9: 61.55
A10: 44256 | B10: 60.54
A11: 44257 | B11: 59.7
A12: 44258 | B12: 61.33
A13: 44259 | B13: 63.81
... A33: 44287 | B33: 61.41
A34: 44288
A35: 44291 | B35: 58.73
A36: 44292 | B36: 59.34
A37: 44293 | B37: 59.77
A38: 44294 | B38: 59.61
A39: 44295 | B39: 59.29
A40: 44298 | B40: 59.7
A41: 44299 | B41: 60.2
A42: 44300 | B42: 63.15
A43: 44301 | B43: 63.42
A44: 44302 | B44: 63.16
A45: 44305 | B45: 63.33
A46: 44306 | B46: 62.61
... A74: 44344 | B74: 66.31
A75: 44347
A76: 44348 | B76: 67.8
A77: 44349 | B77: 68.79
A78: 44350 | B78: 68.81
A79: 44351 | B79: 69.57
A80: 44354 | B80: 69.21
A81: 44355 | B81: 70.11
A82: 44356 | B82: 69.9
A83: 44357 | B83: 70.34
A84: 44358 | B84: 71
A85: 44361 | B85: 70.94
A86: 44362 | B86: 72.06
...

Sheet Кейс1-Исмаилова Нубар
A1: observation_date | B1: Таймер | C1: DCOILWTICO | D1: DCOILWTICO | E1: Уровень ряда | F1: Абсолютное изменение ЦЕПНОЕ | G1: Абсолютное изменение БАЗИСНОЕ | H1: Ускорение | I1: Темп роста ЦЕПНОЙ % | J1: Темп роста БАЗИСНЫЙ % | K1: Темп прироста ЦЕПНОЙ % | L1: Темп прироста БАЗИСНЫЙ % | AE1: Номер периода | AF1: Уровень ряда | AG1: Абсолютное изменение | AH1: Ускорение | AI1: Темп роста к предыдущему % | AJ1: Темп роста к начальному %
A2: 44244 | B2: 1 | C2: =VLOOKUP(A2,Daily!$A:$B,2,0) -> 61.09 | D2: 61.09 | E2: =D2 -> 61.09 | J2: 100 | L2: 0 | AE2: 1 | AF2: =E2 -> 61.09 | AJ2: 100
A3: =A2+1 -> 44245 | B3: 2 | C3: =VLOOKUP(A3, Daily!$A:$B, 2, 0) -> 60.4 | D3: 60.4 | E3: =D3 -> 60.4 | F3: =D3-D2 -> -0.69 | G3: =D3-$D$2 -> -0.69 | I3: =(D3/D2)*100 -> 98.870519 | J3: =(D3/$D$2)*100 -> 98.870519 | K3: =((D3/D2)-1)*100 -> -1.1294811 | L3: =((D3/$D$2)-1)*100 -> -1.1294811 | V3: Карман | W3: Частота | AE3: 2 | AF3: =E3 -> 60.4 | AG3: =F3 -> -0.69 | AI3: =I3 -> 98.870519 | AJ3: =J3 -> 98.870519
A4: =A3+1 -> 44246 | B4: 3 | C4: =VLOOKUP(A4, Daily!$A:$B, 2, 0) -> 59.12 | D4: 59.12 | E4: =D4 -> 59.12 | F4: =D4-D3 -> -1.28 | G4: =D4-$D$2 -> -1.97 | H4: =F4-F3 -> -0.59 | I4: =(D4/D3)*100 -> 97.880795 | J4: =(D4/$D$2)*100 -> 96.77525 | K4: =((D4/D3)-1)*100 -> -2.1192053 | L4: =((D4/$D$2)-1)*100 -> -3.2247504 | V4: 55.44 | W4: 1 | AE4: 3 | AF4: =E4 -> 59.12 | AG4: =F4 -> -1.28 | AH4: =H4 -> -0.59 | AI4: =I4 -> 97.880795 | AJ4: =J4 -> 96.77525
A5: =A4+1 -> 44247 | B5: 4 | C5: =VLOOKUP(A5, Daily!$A:$B, 2, 0) -> #N/A | D5: 59.12 | E5: =D5 -> 59.12 | F5: =D5-D4 -> 0 | G5: =D5-$D$2 -> -1.97 | H5: =F5-F4 -> 1.28 | I5: =(D5/D4)*100 -> 100 | J5: =(D5/$D$2)*100 -> 96.77525 | K5: =((D5/D4)-1)*100 -> 0 | L5: =((D5/$D$2)-1)*100 -> -3.2247504 | V5: 57.06381 | W5: 10 | AE5: 4 | AF5: =E5 -> 59.12 | AG5: =F5 -> 0 | AH5: =H5 -> 1.28 | AI5: =I5 -> 100 | AJ5: =J5 -> 96.77525
A6: =A5+1 -> 44248 | B6: 5 | C6: =VLOOKUP(A6, Daily!$A:$B, 2, 0) -> #N/A | D6: 61.67 | E6: =D6 -> 61.67 | F6: =D6-D5 -> 2.55 | G6: =D6-$D$2 -> 0.58 | H6: =F6-F5 -> 2.55 | I6: =(D6/D5)*100 -> 104.31326 | J6: =(D6/$D$2)*100 -> 100.94942 | K6: =((D6/D5)-1)*100 -> 4.3132612 | L6: =((D6/$D$2)-1)*100 -> 0.94941889 | V6: 58.687619 | W6: 31 | AE6: 5 | AF6: =E6 -> 61.67 | AG6: =F6 -> 2.55 | AH6: =H6 -> 2.55 | AI6: =I6 -> 104.31326 | AJ6: =J6 -> 100.94942
A7: =A6+1 -> 44249 | B7: 6 | C7: =VLOOKUP(A7, Daily!$A:$B, 2, 0) -> 61.67 | D7: 61.67 | E7: =D7 -> 61.67 | F7: =D7-D6 -> 0 | G7: =D7-$D$2 -> 0.58 | H7: =F7-F6 -> -2.55 | I7: =(D7/D6)*100 -> 100 | J7: =(D7/$D$2)*100 -> 100.94942 | K7: =((D7/D6)-1)*100 -> 0 | L7: =((D7/$D$2)-1)*100 -> 0.94941889 | V7: 60.311429 | W7: 60 | AE7: 6 | AF7: =E7 -> 61.67 | AG7: =F7 -> 0 | AH7: =H7 -> -2.55 | AI7: =I7 -> 100 | AJ7: =J7 -> 100.94942
A8: =A7+1 -> 44250 | B8: 7 | C8: =VLOOKUP(A8, Daily!$A:$B, 2, 0) -> 61.66 | D8: 61.66 | E8: =D8 -> 61.66 | F8: =D8-D7 -> -0.01 | G8: =D8-$D$2 -> 0.57 | H8: =F8-F7 -> -0.01 | I8: =(D8/D7)*100 -> 99.983785 | J8: =(D8/$D$2)*100 -> 100.93305 | K8: =((D8/D7)-1)*100 -> -0.01621534 | L8: =((D8/$D$2)-1)*100 -> 0.9330496 | V8: 61.935238 | W8: 72 | AE8: 7 | AF8: =E8 -> 61.66 | AG8: =F8 -> -0.01 | AH8: =H8 -> -0.01 | AI8: =I8 -> 99.983785 | AJ8: =J8 -> 100.93305
A9: =A8+1 -> 44251 | B9: 8 | C9: =VLOOKUP(A9, Daily!$A:$B, 2, 0) -> 63.21 | D9: 63.21 | E9: =D9 -> 63.21 | F9: =D9-D8 -> 1.55 | G9: =D9-$D$2 -> 2.12 | H9: =F9-F8 -> 1.56 | I9: =(D9/D8)*100 -> 102.51379 | J9: =(D9/$D$2)*100 -> 103.47029 | K9: =((D9/D8)-1)*100 -> 2.5137853 | L9: =((D9/$D$2)-1)*100 -> 3.4702897 | V9: 63.559048 | W9: 79 | AE9: 8 | AF9: =E9 -> 63.21 | AG9: =F9 -> 1.55 | AH9: =H9 -> 1.56 | AI9: =I9 -> 102.51379 | AJ9: =J9 -> 103.47029
A10: =A9+1 -> 44252 | B10: 9 | C10: =VLOOKUP(A10, Daily!$A:$B, 2, 0) -> 63.43 | D10: 63.43 | E10: =D10 -> 63.43 | F10: =D10-D9 -> 0.22 | G10: =D10-$D$2 -> 2.34 | H10: =F10-F9 -> -1.33 | I10: =(D10/D9)*100 -> 100.34805 | J10: =(D10/$D$2)*100 -> 103.83041 | K10: =((D10/D9)-1)*100 -> 0.3480462 | L10: =((D10/$D$2)-1)*100 -> 3.8304141 | V10: 65.182857 | W10: 80 | AE10: 9 | AF10: =E10 -> 63.43 | AG10: =F10 -> 0.22 | AH10: =H10 -> -1.33 | AI10: =I10 -> 100.34805 | AJ10: =J10 -> 103.83041
A11: =A10+1 -> 44253 | B11: 10 | C11: =VLOOKUP(A11, Daily!$A:$B, 2, 0) -> 61.55 | D11: 61.55 | E11: =D11 -> 61.55 | F11: =D11-D10 -> -1.88 | G11: =D11-$D$2 -> 0.46 | H11: =F11-F10 -> -2.1 | I11: =(D11/D10)*100 -> 97.036103 | J11: =(D11/$D$2)*100 -> 100.75299 | K11: =((D11/D10)-1)*100 -> -2.9638972 | L11: =((D11/$D$2)-1)*100 -> 0.7529874 | V11: 66.806667 | W11: 69 | AE11: 10 | AF11: =E11 -> 61.55 | AG11: =F11 -> -1.88 | AH11: =H11 -> -2.1 | AI11: =I11 -> 97.036103 | AJ11: =J11 -> 100.75299
A12: =A11+1 -> 44254 | B12: 11 | C12: =VLOOKUP(A12, Daily!$A:$B, 2, 0) -> #N/A | D12: 61.55 | E12: =D12 -> 61.55 | F12: =D12-D11 -> 0 | G12: =D12-$D$2 -> 0.46 | H12: =F12-F11 -> 1.88 | I12: =(D12/D11)*100 -> 100 | J12: =(D12/$D$2)*100 -> 100.75299 | K12: =((D12/D11)-1)*100 -> 0 | L12: =((D12/$D$2)-1)*100 -> 0.7529874 | V12: 68.430476 | W12: 69 | AE12: 11 | AF12: =E12 -> 61.55 | AG12: =F12 -> 0 | AH12: =H12 -> 1.88 | AI12: =I12 -> 100 | AJ12: =J12 -> 100.75299
A13: =A12+1 -> 44255 | B13: 12 | C13: =VLOOKUP(A13, Daily!$A:$B, 2, 0) -> #N/A | D13: 60.54 | E13: =D13 -> 60.54 | F13: =D13-D12 -> -1.01 | G13: =D13-$D$2 -> -0.55 | H13: =F13-F12 -> -1.01 | I13: =(D13/D12)*100 -> 98.359058 | J13: =(D13/$D$2)*100 -> 99.099689 | K13: =((D13/D12)-1)*100 -> -1.6409423 | L13: =((D13/$D$2)-1)*100 -> -0.90031102 | V13: 70.054286 | W13: 124 | AE13: 12 | AF13: =E13 -> 60.54 | AG13: =F13 -> -1.01 | AH13: =H13 -> -1.01 | AI13: =I13 -> 98.359058 | AJ13: =J13 -> 99.099689
A14: =A13+1 -> 44256 | B14: 13 | C14: =VLOOKUP(A14, Daily!$A:$B, 2, 0) -> 60.54 | D14: 60.54 | E14: =D14 -> 60.54 | F14: =D14-D13 -> 0 | G14: =D14-$D$2 -> -0.55 | H14: =F14-F13 -> 1.01 | I14: =(D14/D13)*100 -> 100 | J14: =(D14/$D$2)*100 -> 99.099689 | K14: =((D14/D13)-1)*100 -> 0 | L14: =((D14/$D$2)-1)*100 -> -0.90031102 | V14: 71.678095 | W14: 121
A15: =A14+1 -> 44257 | B15: 14 | C15: =VLOOKUP(A15, Daily!$A:$B, 2, 0) -> 59.7 | D15: 59.7 | E15: =D15 -> 59.7 | F15: =D15-D14 -> -0.84 | G15: =D15-$D$2 -> -1.39 | H15: =F15-F14 -> -0.84 | I15: =(D15/D14)*100 -> 98.612488 | J15: =(D15/$D$2)*100 -> 97.724669 | K15: =((D15/D14)-1)*100 -> -1.3875124 | L15: =((D15/$D$2)-1)*100 -> -2.2753315 | N15: АНАЛИЗ РЕЗУЛЬТАТОВ: | O15: 1. Средний уровень цены нефти WTI составил 76,69$ | V15: 73.301905 | W15: 128
A16: =A15+1 -> 44258 | B16: 15 | C16: =VLOOKUP(A16, Daily!$A:$B, 2, 0) -> 61.33 | D16: 61.33 | E16: =D16 -> 61.33 | F16: =D16-D15 -> 1.63 | G16: =D16-$D$2 -> 0.24 | H16: =F16-F15 -> 2.47 | I16: =(D16/D15)*100 -> 102.73032 | J16: =(D16/$D$2)*100 -> 100.39286 | K16: =((D16/D15)-1)*100 -> 2.7303183 | L16: =((D16/$D$2)-1)*100 -> 0.39286299 | O16: 2. Средний дневной прирост: 0,0008$ (практически стабильная цена) | R16: УСКОРЕНИЕ/ЗАМЕДЛЕНИЕ: | V16: 74.925714 | W16: 90
A17: =A16+1 -> 44259 | B17: 16 | C17: =VLOOKUP(A17, Daily!$A:$B, 2, 0) -> 63.81 | D17: 63.81 | E17: =D17 -> 63.81 | F17: =D17-D16 -> 2.48 | G17: =D17-$D$2 -> 2.72 | H17: =F17-F16 -> 0.85 | I17: =(D17/D16)*100 -> 104.0437 | J17: =(D17/$D$2)*100 -> 104.45245 | K17: =((D17/D16)-1)*100 -> 4.043698 | L17: =((D17/$D$2)-1)*100 -> 4.4524472 | O17: 3. Средний темп роста: 100,0013% (незначительный рост) | R17: Диапазон: от -25 до +15 | V17: 76.549524 | W17: 97
A18: =A17+1 -> 44260 | B18: 17 | C18: =VLOOKUP(A18, Daily!$A:$B, 2, 0) -> 66.08 | D18: 66.08 | E18: =D18 -> 66.08 | F18: =D18-D17 -> 2.27 | G18: =D18-$D$2 -> 4.99 | H18: =F18-F17 -> -0.21 | I18: =(D18/D17)*100 -> 103.55744 | J18: =(D18/$D$2)*100 -> 108.16828 | K18: =((D18/D17)-1)*100 -> 3.5574361 | L18: =((D18/$D$2)-1)*100 -> 8.1682763 | N18: 4. Диапазон изменений: | O18: - Абсолютное изменение: от -1,88$ до +2,55$ | R18: Среднее ускорение: около 0 | V18: 78.173333 | W18: 84
A19: =A18+1 -> 44261 | B19: 18 | C19: =VLOOKUP(A19, Daily!$A:$B, 2, 0) -> #N/A | D19: 66.08 | E19: =D19 -> 66.08 | F19: =D19-D18 -> 0 | G19: =D19-$D$2 -> 4.99 | H19: =F19-F18 -> -2.27 | I19: =(D19/D18)*100 -> 100 | J19: =(D19/$D$2)*100 -> 108.16828 | K19: =((D19/D18)-1)*100 -> 0 | L19: =((D19/$D$2)-1)*100 -> 8.1682763 | O19: - Темп роста цепной: от 97,04% до 104,31% | R19: Пики волатильности: 2022 год (резкие скачки) | V19: 79.797143 | W19: 113
A20: =A19+1 -> 44262 | B20: 19 | C20: =VLOOKUP(A20, Daily!$A:$B, 2, 0) -> #N/A | D20: 65.03 | E20: =D20 -> 65.03 | F20: =D20-D19 -> -1.05 | G20: =D20-$D$2 -> 3.94 | H20: =F20-F19 -> -1.05 | I20: =(D20/D19)*100 -> 98.411017 | J20: =(D20/$D$2)*100 -> 106.4495 | K20: =((D20/D19)-1)*100 -> -1.5889831 | L20: =((D20/$D$2)-1)*100 -> 6.4495007 | N20: 5. Вывод: цена нефти демонстрирует высокую волатильность | R20: ХАРАКТЕРИСТИКА: | V20: 81.420952 | W20: 102
A21: =A20+1 -> 44263 | B21: 20 | C21: =VLOOKUP(A21, Daily!$A:$B, 2, 0) -> 65.03 | D21: 65.03 | E21: =D21 -> 65.03 | F21: =D21-D20 -> 0 | G21: =D21-$D$2 -> 3.94 | H21: =F21-F20 -> 1.05 | I21: =(D21/D20)*100 -> 100 | J21: =(D21/$D$2)*100 -> 106.4495 | K21: =((D21/D20)-1)*100 -> 0 | L21: =((D21/$D$2)-1)*100 -> 6.4495007 | N21: АНАЛИЗ РАСПРЕДЕЛЕНИЯ: | R21: - Частая смена знака (положительное ↔ отрицательное) | V21: 83.044762 | W21: 73
A22: =A21+1 -> 44264 | B22: 21 | C22: =VLOOKUP(A22, Daily!$A:$B, 2, 0) -> 64.02 | D22: 64.02 | E22: =D22 -> 64.02 | F22: =D22-D21 -> -1.01 | G22: =D22-$D$2 -> 2.93 | H22: =F22-F21 -> -1.01 | I22: =(D22/D21)*100 -> 98.446871 | J22: =(D22/$D$2)*100 -> 104.7962 | K22: =((D22/D21)-1)*100 -> -1.5531293 | L22: =((D22/$D$2)-1)*100 -> 4.7962023 | N22: Форма: Приближена к нормальному распределению | R22: - 2022: экстремальная волатильность (пики до +15, -20) | V22: 84.668571 | W22: 64
A23: =A22+1 -> 44265 | B23: 22 | C23: =VLOOKUP(A23, Daily!$A:$B, 2, 0) -> 64.45 | D23: 64.45 | E23: =D23 -> 64.45 | F23: =D23-D22 -> 0.43 | G23: =D23-$D$2 -> 3.36 | H23: =F23-F22 -> 1.44 | I23: =(D23/D22)*100 -> 100.67167 | J23: =(D23/$D$2)*100 -> 105.50008 | K23: =((D23/D22)-1)*100 -> 0.6716651 | L23: =((D23/$D$2)-1)*100 -> 5.5000818 | N23: Центр: 60-80$ (наибольшая частота) | R23: - 2023-2026: стабилизация (около 0) | V23: 86.292381 | W23: 51
A24: =A23+1 -> 44266 | B24: 23 | C24: =VLOOKUP(A24, Daily!$A:$B, 2, 0) -> 66.02 | D24: 66.02 | E24: =D24 -> 66.02 | F24: =D24-D23 -> 1.57 | G24: =D24-$D$2 -> 4.93 | H24: =F24-F23 -> 1.14 | I24: =(D24/D23)*100 -> 102.436 | J24: =(D24/$D$2)*100 -> 108.07006 | K24: =((D24/D23)-1)*100 -> 2.4359969 | L24: =((D24/$D$2)-1)*100 -> 8.0700606 | N24: Разброс: от 55$ до 120$ | R24: ВЫВОД: Процесс НЕСТАБИЛЬНЫЙ, | V24: 87.91619 | W24: 45
A25: =A24+1 -> 44267 | B25: 24 | C25: =VLOOKUP(A25, Daily!$A:$B, 2, 0) -> 65.59 | D25: 65.59 | E25: =D25 -> 65.59 | F25: =D25-D24 -> -0.43 | G25: =D25-$D$2 -> 4.5 | H25: =F25-F24 -> -2 | I25: =(D25/D24)*100 -> 99.348682 | J25: =(D25/$D$2)*100 -> 107.36618 | K25: =((D25/D24)-1)*100 -> -0.65131778 | L25: =((D25/$D$2)-1)*100 -> 7.366181 | N25: Среднее: 76,69$ | R25: но после 2022 года наблюдается успокоение рынка | V25: 89.54 | W25: 29
A26: =A25+1 -> 44268 | B26: 25 | C26: =VLOOKUP(A26, Daily!$A:$B, 2, 0) -> #N/A | D26: 65.59 | E26: =D26 -> 65.59 | F26: =D26-D25 -> 0 | G26: =D26-$D$2 -> 4.5 | H26: =F26-F25 -> 0.43 | I26: =(D26/D25)*100 -> 100 | J26: =(D26/$D$2)*100 -> 107.36618 | K26: =((D26/D25)-1)*100 -> 0 | L26: =((D26/$D$2)-1)*100 -> 7.366181 | N26: Вывод: Цены сконцентрированы вокруг 60-80$, присутствуют выбросы выше 100$ (кризисные периоды) | V26: 91.16381 | W26: 19
A27: =A26+1 -> 44269 | B27: 26 | C27: =VLOOKUP(A27, Daily!$A:$B, 2, 0) -> #N/A | D27: 65.36 | E27: =D27 -> 65.36 | F27: =D27-D26 -> -0.23 | G27: =D27-$D$2 -> 4.27 | H27: =F27-F26 -> -0.23 | I27: =(D27/D26)*100 -> 99.649337 | J27: =(D27/$D$2)*100 -> 106.98969 | K27: =((D27/D26)-1)*100 -> -0.35066321 | L27: =((D27/$D$2)-1)*100 -> 6.9896873 | V27: 92.787619 | W27: 31
A28: =A27+1 -> 44270 | B28: 27 | C28: =VLOOKUP(A28, Daily!$A:$B, 2, 0) -> 65.36 | D28: 65.36 | E28: =D28 -> 65.36 | F28: =D28-D27 -> 0 | G28: =D28-$D$2 -> 4.27 | H28: =F28-F27 -> 0.23 | I28: =(D28/D27)*100 -> 100 | J28: =(D28/$D$2)*100 -> 106.98969 | K28: =((D28/D27)-1)*100 -> 0 | L28: =((D28/$D$2)-1)*100 -> 6.9896873 | V28: 94.411429 | W28: 20
A29: =A28+1 -> 44271 | B29: 28 | C29: =VLOOKUP(A29, Daily!$A:$B, 2, 0) -> 64.82 | D29: 64.82 | E29: =D29 -> 64.82 | F29: =D29-D28 -> -0.54 | G29: =D29-$D$2 -> 3.73 | H29: =F29-F28 -> -0.54 | I29: =(D29/D28)*100 -> 99.173807 | J29: =(D29/$D$2)*100 -> 106.10575 | K29: =((D29/D28)-1)*100 -> -0.82619339 | L29: =((D29/$D$2)-1)*100 -> 6.1057456 | V29: 96.035238 | W29: 7
A30: =A29+1 -> 44272 | B30: 29 | C30: =VLOOKUP(A30, Daily!$A:$B, 2, 0) -> 64.55 | D30: 64.55 | E30: =D30 -> 64.55 | F30: =D30-D29 -> -0.27 | G30: =D30-$D$2 -> 3.46 | H30: =F30-F29 -> 0.27 | I30: =(D30/D29)*100 -> 99.583462 | J30: =(D30/$D$2)*100 -> 105.66377 | K30: =((D30/D29)-1)*100 -> -0.41653811 | L30: =((D30/$D$2)-1)*100 -> 5.6637748 | V30: 97.659048 | W30: 12
A31: =A30+1 -> 44273 | B31: 30 | C31: =VLOOKUP(A31, Daily!$A:$B, 2, 0) -> 59.95 | D31: 59.95 | E31: =D31 -> 59.95 | F31: =D31-D30 -> -4.6 | G31: =D31-$D$2 -> -1.14 | H31: =F31-F30 -> -4.33 | I31: =(D31/D30)*100 -> 92.873741 | J31: =(D31/$D$2)*100 -> 98.133901 | K31: =((D31/D30)-1)*100 -> -7.1262587 | L31: =((D31/$D$2)-1)*100 -> -1.8660992 | V31: 99.282857 | W31: 10
A32: =A31+1 -> 44274 | B32: 31 | C32: =VLOOKUP(A32, Daily!$A:$B, 2, 0) -> 61.43 | D32: 61.43 | E32: =D32 -> 61.43 | F32: =D32-D31 -> 1.48 | G32: =D32-$D$2 -> 0.34 | H32: =F32-F31 -> 6.08 | I32: =(D32/D31)*100 -> 102.46872 | J32: =(D32/$D$2)*100 -> 100.55656 | K32: =((D32/D31)-1)*100 -> 2.4687239 | L32: =((D32/$D$2)-1)*100 -> 0.5565559 | V32: 100.90667 | W32: 13
A33: =A32+1 -> 44275 | B33: 32 | C33: =VLOOKUP(A33, Daily!$A:$B, 2, 0) -> #N/A | D33: 61.43 | E33: =D33 -> 61.43 | F33: =D33-D32 -> 0 | G33: =D33-$D$2 -> 0.34 | H33: =F33-F32 -> -1.48 | I33: =(D33/D32)*100 -> 100 | J33: =(D33/$D$2)*100 -> 100.55656 | K33: =((D33/D32)-1)*100 -> 0 | L33: =((D33/$D$2)-1)*100 -> 0.5565559 | V33: 102.53048 | W33: 8
A34: =A33+1 -> 44276 | B34: 33 | C34: =VLOOKUP(A34, Daily!$A:$B, 2, 0) -> #N/A | D34: 61.48 | E34: =D34 -> 61.48 | F34: =D34-D33 -> 0.05 | G34: =D34-$D$2 -> 0.39 | H34: =F34-F33 -> 0.05 | I34: =(D34/D33)*100 -> 100.08139 | J34: =(D34/$D$2)*100 -> 100.6384 | K34: =((D34/D33)-1)*100 -> 0.081393456 | L34: =((D34/$D$2)-1)*100 -> 0.63840236 | V34: 104.15429 | W34: 14
A35: =A34+1 -> 44277 | B35: 34 | C35: =VLOOKUP(A35, Daily!$A:$B, 2, 0) -> 61.48 | D35: 61.48 | E35: =D35 -> 61.48 | F35: =D35-D34 -> 0 | G35: =D35-$D$2 -> 0.39 | H35: =F35-F34 -> -0.05 | I35: =(D35/D34)*100 -> 100 | J35: =(D35/$D$2)*100 -> 100.6384 | K35: =((D35/D34)-1)*100 -> 0 | L35: =((D35/$D$2)-1)*100 -> 0.63840236 | V35: 105.7781 | W35: 15
A36: =A35+1 -> 44278 | B36: 35 | C36: =VLOOKUP(A36, Daily!$A:$B, 2, 0) -> 57.75 | D36: 57.75 | E36: =D36 -> 57.75 | F36: =D36-D35 -> -3.73 | G36: =D36-$D$2 -> -3.34 | H36: =F36-F35 -> -3.73 | I36: =(D36/D35)*100 -> 93.932986 | J36: =(D36/$D$2)*100 -> 94.532657 | K36: =((D36/D35)-1)*100 -> -6.0670137 | L36: =((D36/$D$2)-1)*100 -> -5.4673433 | V36: 107.4019 | W36: 11
A37: =A36+1 -> 44279 | B37: 36 | C37: =VLOOKUP(A37, Daily!$A:$B, 2, 0) -> 61.12 | D37: 61.12 | E37: =D37 -> 61.12 | F37: =D37-D36 -> 3.37 | G37: =D37-$D$2 -> 0.03 | H37: =F37-F36 -> 7.1 | I37: =(D37/D36)*100 -> 105.8355 | J37: =(D37/$D$2)*100 -> 100.04911 | K37: =((D37/D36)-1)*100 -> 5.8354978 | L37: =((D37/$D$2)-1)*100 -> 0.049107874 | V37: 109.02571 | W37: 10
A38: =A37+1 -> 44280 | B38: 37 | C38: =VLOOKUP(A38, Daily!$A:$B, 2, 0) -> 58.47 | D38: 58.47 | E38: =D38 -> 58.47 | F38: =D38-D37 -> -2.65 | G38: =D38-$D$2 -> -2.62 | H38: =F38-F37 -> -6.02 | I38: =(D38/D37)*100 -> 95.664267 | J38: =(D38/$D$2)*100 -> 95.711246 | K38: =((D38/D37)-1)*100 -> -4.335733 | L38: =((D38/$D$2)-1)*100 -> -4.2887543 | V38: 110.64952 | W38: 18
... A40: =A39+1 -> 44282 | B40: 39 | C40: =VLOOKUP(A40, Daily!$A:$B, 2, 0) -> #N/A | D40: 60.93 | E40: =D40 -> 60.93 | F40: =D40-D39 -> 0 | G40: =D40-$D$2 -> -0.16 | H40: =F40-F39 -> -2.46 | I40: =(D40/D39)*100 -> 100 | J40: =(D40/$D$2)*100 -> 99.738091 | K40: =((D40/D39)-1)*100 -> 0 | L40: =((D40/$D$2)-1)*100 -> -0.26190866 | V40: 113.89714 | W40: 6
A41: =A40+1 -> 44283 | B41: 40 | C41: =VLOOKUP(A41, Daily!$A:$B, 2, 0) -> #N/A | D41: 61.49 | E41: =D41 -> 61.49 | F41: =D41-D40 -> 0.56 | G41: =D41-$D$2 -> 0.4 | H41: =F41-F40 -> 0.56 | I41: =(D41/D40)*100 -> 100.91909 | J41: =(D41/$D$2)*100 -> 100.65477 | K41: =((D41/D40)-1)*100 -> 0.91908748 | L41: =((D41/$D$2)-1)*100 -> 0.65477165 | R41: ЕЖЕДНЕВНЫЙ ТЕМП РОСТА: | V41: 115.52095 | W41: 11
...

Sheet вероятностный анализ
A1: Диапазон цен | B1: Количество дней | C1: Вероятность (частота) | D1: Накопленная частота
A2: 58-60 | B2: =COUNTIFS('Кейс1-Исмаилова Нубар'!$D$2:$D$1828,">=58",'Кейс1-Исмаилова Нубар'!$D$2:$D$1828,"<60") -> 69 | C2: =B2/1827 -> 0.037766831 | D2: =C2 -> 0.037766831
A3: 60-62 | B3: =COUNTIFS('Кейс1-Исмаилова Нубар'!$D$2:$D$1828,">=60",'Кейс1-Исмаилова Нубар'!$D$2:$D$1828,"<62") -> 85 | C3: =B3/1827 -> 0.046524357 | D3: =D2+C3 -> 0.084291188
A4: 62-64 | B4: =COUNTIFS('Кейс1-Исмаилова Нубар'!$D$2:$D$1828,">=62",'Кейс1-Исмаилова Нубар'!$D$2:$D$1828,"<64") -> 101 | C4: =B4/1827 -> 0.055281883 | D4: =D3+C4 -> 0.13957307
A5: 64-66 | B5: =COUNTIFS('Кейс1-Исмаилова Нубар'!$D$2:$D$1828,">=64",'Кейс1-Исмаилова Нубар'!$D$2:$D$1828,"<66") -> 83 | C5: =B5/1827 -> 0.045429666 | D5: =D4+C5 -> 0.18500274
A6: 66-68 | B6: =COUNTIFS('Кейс1-Исмаилова Нубар'!$D$2:$D$1828,">=66",'Кейс1-Исмаилова Нубар'!$D$2:$D$1828,"<68") -> 80 | C6: =B6/1827 -> 0.04378763 | D6: =D5+C6 -> 0.22879037
A8: АНАЛИЗ ВЕРОЯТНОСТНОГО РАСПРЕДЕЛЕНИЯ:
A9: 1. Распределение цен нефти WTI за период | D9: 2. Наиболее вероятный диапазон цен: 62-64$
A10: (февраль-март 2021, 1827 дней): | D10: - Количество дней: 101
A11: 3. Наименее вероятный диапазон: 58-60$ | D11: - Вероятность: 5,53%
A12: - Количество дней: 69 | D12: - Это самый частый диапазон цен
A13: - Вероятность: 3,78% | D13: 4. Накопленная частота показывает:
A14: - Низкие цены встречались реже | D14: - 22,89% всех цен находятся в диапазоне 58-68$
A15: Вывод: цены распределены достаточно | D15: - Распределение относительно равномерное
A16: равномерно с небольшим преобладанием
A17: средних значений (62-64$)

Sheet коррелограмма
A35: ХАРАКТЕРИСТИКА АВТОКОРРЕЛЯЦИИ (ACF):
A37: Лаг 1: 0.9919 (очень высокая корреляция) | E37: ЧАСТИЧНАЯ АВТОКОРРЕЛЯЦИЯ (PACF): | H37: СТАТИСТИЧЕСКАЯ ЗНАЧИМОСТЬ:
A38: Лаг 20: 0.8931 (всё ещё высокая) | K38: ВЫВОДЫ:
E39: Резкий пик на лаге 1: 0.9919 (***) | H39: Все p-значения = 0.000 < 0.01
A40: Все 25 лагов статистически значимы (***) | E40: На лагах 2-20: значения близки к 0 | H40: Автокорреляция не случайна | K40: Ряд НЕСТАЦИОНАРЕН (требует дифференцирования)
A41: Медленное затухание = нестационарный ряд
A42: Цены сильно зависят от предыдущих значений
AC44: 0.85219983 | AD44: 1 | AE44: =100-2-AD44 -> 97 | AF44: =AC44/SQRT(1-AC44*AC44)*SQRT(AE44) -> 16.041535 | AG44: =_xlfn.T.INV.2T(0.05,AE44) -> 1.9847232 | AH44: =AG44*AG44 -> 3.9391261 | AI44: =SQRT(AH44/(AE44+AH44)) -> 0.19754688 | AJ44: =-AI44 -> -0.19754688
C45: 1 | D45: 2 | E45: 3 | F45: 4 | G45: 5 | H45: 6 | I45: 7 | J45: 8 | K45: 9 | L45: 10 | M45: 11 | N45: 12 | O45: 13 | P45: 14 | Q45: 15 | R45: 16 | S45: 17 | T45: 18 | U45: 19 | V45: 20 | W45: 21 | X45: 22 | Y45: 23 | Z45: 24 | AA45: 25 | AC45: 0.74863222 | AD45: 2 | AE45: =100-2-AD45 -> 96 | AF45: =AC45/SQRT(1-AC45*AC45)*SQRT(AE45) -> 11.063692 | AG45: =_xlfn.T.INV.2T(0.05,AE45) -> 1.9849843 | AH45: =AG45*AG45 -> 3.9401627 | AI45: =SQRT(AH45/(AE45+AH45)) -> 0.19855785 | AJ45: =-AI45 -> -0.19855785
C46: =CORREL($B$49:$B$147,C49:C147) -> 0.85219983 | D46: =CORREL($B$50:$B$147,D50:D147) -> 0.74863222 | E46: =CORREL($B$51:$B$147,E51:E147) -> 0.6202842 | F46: =CORREL($B$52:$B$147,F52:F147) -> 0.55003045 | G46: =CORREL($B$53:$B$147,G53:G147) -> 0.50561145 | H46: =CORREL($B$54:$B$147,H54:H147) -> 0.45035136 | I46: =CORREL($B$55:$B$147,I55:I147) -> 0.42465053 | J46: =CORREL($B$56:$B$147,J56:J147) -> 0.40661124 | K46: =CORREL($B$57:$B$147,K57:K147) -> 0.38079013 | L46: =CORREL($B$58:$B$147,L58:L147) -> 0.33296578 | M46: =CORREL($B$59:$B$147,M59:M147) -> 0.28606359 | N46: =CORREL($B$60:$B$147,N60:N147) -> 0.23528537 | O46: =CORREL($B$61:$B$147,O61:O147) -> 0.17128757 | P46: =CORREL($B$62:$B$147,P62:P147) -> 0.087449782 | Q46: =CORREL($B$63:$B$147,Q63:Q147) -> 0.084387068 | R46: =CORREL($B$64:$B$147,R64:R147) -> 0.088243822 | S46: =CORREL($B$65:$B$147,S65:S147) -> 0.095667402 | T46: =CORREL($B$66:$B$147,T66:T147) -> 0.071697398 | U46: =CORREL($B$67:$B$147,U67:U147) -> 0.013156482 | V46: =CORREL($B$68:$B$147,V68:V147) -> -0.048152946 | W46: =CORREL($B$69:$B$147,W69:W147) -> -0.087174549 | X46: =CORREL($B$70:$B$147,X70:X147) -> -0.15583066 | Y46: =CORREL($B$71:$B$147,Y71:Y147) -> -0.20739961 | Z46: =CORREL($B$72:$B$147,Z72:Z147) -> -0.27835223 | AA46: =CORREL($B$73:$B$147,AA73:AA147) -> -0.31211562 | AC46: 0.6202842 | AD46: 3 | AE46: =100-2-AD46 -> 95 | AF46: =AC46/SQRT(1-AC46*AC46)*SQRT(AE46) -> 7.7077495 | AG46: =_xlfn.T.INV.2T(0.05,AE46) -> 1.985251 | AH46: =AG46*AG46 -> 3.9412215 | AI46: =SQRT(AH46/(AE46+AH46)) -> 0.19958449 | AJ46: =-AI46 -> -0.19958449
A47: Период | B47: Цена_нефти | AC47: 0.55003045 | AD47: 4 | AE47: =100-2-AD47 -> 94 | AF47: =AC47/SQRT(1-AC47*AC47)*SQRT(AE47) -> 6.3854129 | AG47: =_xlfn.T.INV.2T(0.05,AE47) -> 1.9855234 | AH47: =AG47*AG47 -> 3.9423033 | AI47: =SQRT(AH47/(AE47+AH47)) -> 0.20062722 | AJ47: =-AI47 -> -0.20062722
A48: 44244 | B48: 61.09 | AC48: 0.50561145 | AD48: 5 | AE48: =100-2-AD48 -> 93 | AF48: =AC48/SQRT(1-AC48*AC48)*SQRT(AE48) -> 5.6515519 | AG48: =_xlfn.T.INV.2T(0.05,AE48) -> 1.9858018 | AH48: =AG48*AG48 -> 3.9434088 | AI48: =SQRT(AH48/(AE48+AH48)) -> 0.20168647 | AJ48: =-AI48 -> -0.20168647
A49: =A48+1 -> 44245 | B49: 60.4 | C49: 61.09 | AC49: 0.45035136 | AD49: 6 | AE49: =100-2-AD49 -> 92 | AF49: =AC49/SQRT(1-AC49*AC49)*SQRT(AE49) -> 4.8380037 | AG49: =_xlfn.T.INV.2T(0.05,AE49) -> 1.9860863 | AH49: =AG49*AG49 -> 3.9445389 | AI49: =SQRT(AH49/(AE49+AH49)) -> 0.20276266 | AJ49: =-AI49 -> -0.20276266
A50: =A49+1 -> 44246 | B50: 59.12 | C50: 60.4 | D50: 61.09 | AC50: 0.42465053 | AD50: 7 | AE50: =100-2-AD50 -> 91 | AF50: =AC50/SQRT(1-AC50*AC50)*SQRT(AE50) -> 4.4743746 | AG50: =_xlfn.T.INV.2T(0.05,AE50) -> 1.9863772 | AH50: =AG50*AG50 -> 3.9456942 | AI50: =SQRT(AH50/(AE50+AH50)) -> 0.20385627 | AJ50: =-AI50 -> -0.20385627
A51: =A50+1 -> 44247 | B51: 59.12 | C51: 59.12 | D51: 60.4 | E51: 61.09 | AC51: 0.40661124 | AD51: 8 | AE51: =100-2-AD51 -> 90 | AF51: =AC51/SQRT(1-AC51*AC51)*SQRT(AE51) -> 4.2222499 | AG51: =_xlfn.T.INV.2T(0.05,AE51) -> 1.9866745 | AH51: =AG51*AG51 -> 3.9468757 | AI51: =SQRT(AH51/(AE51+AH51)) -> 0.20496776 | AJ51: =-AI51 -> -0.20496776
A52: =A51+1 -> 44248 | B52: 61.67 | C52: 59.12 | D52: 59.12 | E52: 60.4 | F52: 61.09 | AC52: 0.38079013 | AD52: 9 | AE52: =100-2-AD52 -> 89 | AF52: =AC52/SQRT(1-AC52*AC52)*SQRT(AE52) -> 3.8850617 | AG52: =_xlfn.T.INV.2T(0.05,AE52) -> 1.9869787 | AH52: =AG52*AG52 -> 3.9480844 | AI52: =SQRT(AH52/(AE52+AH52)) -> 0.20609763 | AJ52: =-AI52 -> -0.20609763
A53: =A52+1 -> 44249 | B53: 61.67 | C53: 61.67 | D53: 59.12 | E53: 59.12 | F53: 60.4 | G53: 61.09 | AC53: 0.33296578 | AD53: 10 | AE53: =100-2-AD53 -> 88 | AF53: =AC53/SQRT(1-AC53*AC53)*SQRT(AE53) -> 3.3125114 | AG53: =_xlfn.T.INV.2T(0.05,AE53) -> 1.9872899 | AH53: =AG53*AG53 -> 3.949321 | AI53: =SQRT(AH53/(AE53+AH53)) -> 0.20724638 | AJ53: =-AI53 -> -0.20724638
A54: =A53+1 -> 44250 | B54: 61.66 | C54: 61.67 | D54: 61.67 | E54: 59.12 | F54: 59.12 | G54: 60.4 | H54: 61.09 | AC54: 0.28606359 | AD54: 11 | AE54: =100-2-AD54 -> 87 | AF54: =AC54/SQRT(1-AC54*AC54)*SQRT(AE54) -> 2.7845898 | AG54: =_xlfn.T.INV.2T(0.05,AE54) -> 1.9876083 | AH54: =AG54*AG54 -> 3.9505867 | AI54: =SQRT(AH54/(AE54+AH54)) -> 0.20841455 | AJ54: =-AI54 -> -0.20841455
A55: =A54+1 -> 44251 | B55: 63.21 | C55: 61.66 | D55: 61.67 | E55: 61.67 | F55: 59.12 | G55: 59.12 | H55: 60.4 | I55: 61.09 | AC55: 0.23528537 | AD55: 12 | AE55: =100-2-AD55 -> 86 | AF55: =AC55/SQRT(1-AC55*AC55)*SQRT(AE55) -> 2.2449713 | AG55: =_xlfn.T.INV.2T(0.05,AE55) -> 1.9879342 | AH55: =AG55*AG55 -> 3.9518824 | AI55: =SQRT(AH55/(AE55+AH55)) -> 0.2096027 | AJ55: =-AI55 -> -0.2096027
A56: =A55+1 -> 44252 | B56: 63.43 | C56: 63.21 | D56: 61.66 | E56: 61.67 | F56: 61.67 | G56: 59.12 | H56: 59.12 | I56: 60.4 | J56: 61.09 | AC56: 0.17128757 | AD56: 13 | AE56: =100-2-AD56 -> 85 | AF56: =AC56/SQRT(1-AC56*AC56)*SQRT(AE56) -> 1.6028823 | AG56: =_xlfn.T.INV.2T(0.05,AE56) -> 1.9882679 | AH56: =AG56*AG56 -> 3.9532093 | AI56: =SQRT(AH56/(AE56+AH56)) -> 0.2108114 | AJ56: =-AI56 -> -0.2108114
A57: =A56+1 -> 44253 | B57: 61.55 | C57: 63.43 | D57: 63.21 | E57: 61.66 | F57: 61.67 | G57: 61.67 | H57: 59.12 | I57: 59.12 | J57: 60.4 | K57: 61.09 | AC57: 0.087449782 | AD57: 14 | AE57: =100-2-AD57 -> 84 | AF57: =AC57/SQRT(1-AC57*AC57)*SQRT(AE57) -> 0.80457287 | AG57: =_xlfn.T.INV.2T(0.05,AE57) -> 1.9886097 | AH57: =AG57*AG57 -> 3.9545684 | AI57: =SQRT(AH57/(AE57+AH57)) -> 0.21204124 | AJ57: =-AI57 -> -0.21204124
A58: =A57+1 -> 44254 | B58: 61.55 | C58: 61.55 | D58: 63.43 | E58: 63.21 | F58: 61.66 | G58: 61.67 | H58: 61.67 | I58: 59.12 | J58: 59.12 | K58: 60.4 | L58: 61.09 | AC58: 0.084387068 | AD58: 15 | AE58: =100-2-AD58 -> 83 | AF58: =AC58/SQRT(1-AC58*AC58)*SQRT(AE58) -> 0.77155487 | AG58: =_xlfn.T.INV.2T(0.05,AE58) -> 1.9889598 | AH58: =AG58*AG58 -> 3.955961 | AI58: =SQRT(AH58/(AE58+AH58)) -> 0.21329286 | AJ58: =-AI58 -> -0.21329286
A59: =A58+1 -> 44255 | B59: 60.54 | C59: 61.55 | D59: 61.55 | E59: 63.43 | F59: 63.21 | G59: 61.66 | H59: 61.67 | I59: 61.67 | J59: 59.12 | K59: 59.12 | L59: 60.4 | M59: 61.09 | AC59: 0.088243822 | AD59: 16 | AE59: =100-2-AD59 -> 82 | AF59: =AC59/SQRT(1-AC59*AC59)*SQRT(AE59) -> 0.8022113 | AG59: =_xlfn.T.INV.2T(0.05,AE59) -> 1.9893186 | AH59: =AG59*AG59 -> 3.9573883 | AI59: =SQRT(AH59/(AE59+AH59)) -> 0.2145669 | AJ59: =-AI59 -> -0.2145669
A60: =A59+1 -> 44256 | B60: 60.54 | C60: 60.54 | D60: 61.55 | E60: 61.55 | F60: 63.43 | G60: 63.21 | H60: 61.66 | I60: 61.67 | J60: 61.67 | K60: 59.12 | L60: 59.12 | M60: 60.4 | N60: 61.09 | AC60: 0.095667402 | AD60: 17 | AE60: =100-2-AD60 -> 81 | AF60: =AC60/SQRT(1-AC60*AC60)*SQRT(AE60) -> 0.86497395 | AG60: =_xlfn.T.INV.2T(0.05,AE60) -> 1.9896863 | AH60: =AG60*AG60 -> 3.9588517 | AI60: =SQRT(AH60/(AE60+AH60)) -> 0.21586404 | AJ60: =-AI60 -> -0.21586404
A61: =A60+1 -> 44257 | B61: 59.7 | C61: 60.54 | D61: 60.54 | E61: 61.55 | F61: 61.55 | G61: 63.43 | H61: 63.21 | I61: 61.66 | J61: 61.67 | K61: 61.67 | L61: 59.12 | M61: 59.12 | N61: 60.4 | O61: 61.09 | AC61: 0.071697398 | AD61: 18 | AE61: =100-2-AD61 -> 80 | AF61: =AC61/SQRT(1-AC61*AC61)*SQRT(AE61) -> 0.64293567 | AG61: =_xlfn.T.INV.2T(0.05,AE61) -> 1.9900634 | AH61: =AG61*AG61 -> 3.9603524 | AI61: =SQRT(AH61/(AE61+AH61)) -> 0.21718498 | AJ61: =-AI61 -> -0.21718498
A62: =A61+1 -> 44258 | B62: 61.33 | C62: 59.7 | D62: 60.54 | E62: 60.54 | F62: 61.55 | G62: 61.55 | H62: 63.43 | I62: 63.21 | J62: 61.66 | K62: 61.67 | L62: 61.67 | M62: 59.12 | N62: 59.12 | O62: 60.4 | P62: 61.09 | AC62: 0.013156482 | AD62: 19 | AE62: =100-2-AD62 -> 79 | AF62: =AC62/SQRT(1-AC62*AC62)*SQRT(AE62) -> 0.1169475 | AG62: =_xlfn.T.INV.2T(0.05,AE62) -> 1.9904502 | AH62: =AG62*AG62 -> 3.961892 | AI62: =SQRT(AH62/(AE62+AH62)) -> 0.21853047 | AJ62: =-AI62 -> -0.21853047
A63: =A62+1 -> 44259 | B63: 63.81 | C63: 61.33 | D63: 59.7 | E63: 60.54 | F63: 60.54 | G63: 61.55 | H63: 61.55 | I63: 63.43 | J63: 63.21 | K63: 61.66 | L63: 61.67 | M63: 61.67 | N63: 59.12 | O63: 59.12 | P63: 60.4 | Q63: 61.09 | AC63: -0.048152946 | AD63: 20 | AE63: =100-2-AD63 -> 78 | AF63: =AC63/SQRT(1-AC63*AC63)*SQRT(AE63) -> -0.42576921 | AG63: =_xlfn.T.INV.2T(0.05,AE63) -> 1.9908471 | AH63: =AG63*AG63 -> 3.9634721 | AI63: =SQRT(AH63/(AE63+AH63)) -> 0.21990126 | AJ63: =-AI63 -> -0.21990126
A64: =A63+1 -> 44260 | B64: 66.08 | C64: 63.81 | D64: 61.33 | E64: 59.7 | F64: 60.54 | G64: 60.54 | H64: 61.55 | I64: 61.55 | J64: 63.43 | K64: 63.21 | L64: 61.66 | M64: 61.67 | N64: 61.67 | O64: 59.12 | P64: 59.12 | Q64: 60.4 | R64: 61.09 | AC64: -0.087174549 | AD64: 21 | AE64: =100-2-AD64 -> 77 | AF64: =AC64/SQRT(1-AC64*AC64)*SQRT(AE64) -> -0.76787683 | AG64: =_xlfn.T.INV.2T(0.05,AE64) -> 1.9912544 | AH64: =AG64*AG64 -> 3.9650941 | AI64: =SQRT(AH64/(AE64+AH64)) -> 0.22129818 | AJ64: =-AI64 -> -0.22129818
A65: =A64+1 -> 44261 | B65: 66.08 | C65: 66.08 | D65: 63.81 | E65: 61.33 | F65: 59.7 | G65: 60.54 | H65: 60.54 | I65: 61.55 | J65: 61.55 | K65: 63.43 | L65: 63.21 | M65: 61.66 | N65: 61.67 | O65: 61.67 | P65: 59.12 | Q65: 59.12 | R65: 60.4 | S65: 61.09 | AC65: -0.15583066 | AD65: 22 | AE65: =100-2-AD65 -> 76 | AF65: =AC65/SQRT(1-AC65*AC65)*SQRT(AE65) -> -1.3753011 | AG65: =_xlfn.T.INV.2T(0.05,AE65) -> 1.9916726 | AH65: =AG65*AG65 -> 3.9667598 | AI65: =SQRT(AH65/(AE65+AH65)) -> 0.22272204 | AJ65: =-AI65 -> -0.22272204
A66: =A65+1 -> 44262 | B66: 65.03 | C66: 66.08 | D66: 66.08 | E66: 63.81 | F66: 61.33 | G66: 59.7 | H66: 60.54 | I66: 60.54 | J66: 61.55 | K66: 61.55 | L66: 63.43 | M66: 63.21 | N66: 61.66 | O66: 61.67 | P66: 61.67 | Q66: 59.12 | R66: 59.12 | S66: 60.4 | T66: 61.09 | AC66: -0.20739961 | AD66: 23 | AE66: =100-2-AD66 -> 75 | AF66: =AC66/SQRT(1-AC66*AC66)*SQRT(AE66) -> -1.836056 | AG66: =_xlfn.T.INV.2T(0.05,AE66) -> 1.9921022 | AH66: =AG66*AG66 -> 3.968471 | AI66: =SQRT(AH66/(AE66+AH66)) -> 0.22417374 | AJ66: =-AI66 -> -0.22417374
A67: =A66+1 -> 44263 | B67: 65.03 | C67: 65.03 | D67: 66.08 | E67: 66.08 | F67: 63.81 | G67: 61.33 | H67: 59.7 | I67: 60.54 | J67: 60.54 | K67: 61.55 | L67: 61.55 | M67: 63.43 | N67: 63.21 | O67: 61.66 | P67: 61.67 | Q67: 61.67 | R67: 59.12 | S67: 59.12 | T67: 60.4 | U67: 61.09 | AC67: -0.27835223 | AD67: 24 | AE67: =100-2-AD67 -> 74 | AF67: =AC67/SQRT(1-AC67*AC67)*SQRT(AE67) -> -2.4930022 | AG67: =_xlfn.T.INV.2T(0.05,AE67) -> 1.9925435 | AH67: =AG67*AG67 -> 3.9702296 | AI67: =SQRT(AH67/(AE67+AH67)) -> 0.22565419 | AJ67: =-AI67 -> -0.22565419
A68: =A67+1 -> 44264 | B68: 64.02 | C68: 65.03 | D68: 65.03 | E68: 66.08 | F68: 66.08 | G68: 63.81 | H68: 61.33 | I68: 59.7 | J68: 60.54 | K68: 60.54 | L68: 61.55 | M68: 61.55 | N68: 63.43 | O68: 63.21 | P68: 61.66 | Q68: 61.67 | R68: 61.67 | S68: 59.12 | T68: 59.12 | U68: 60.4 | V68: 61.09 | AC68: -0.31211562 | AD68: 25 | AE68: =100-2-AD68 -> 73 | AF68: =AC68/SQRT(1-AC68*AC68)*SQRT(AE68) -> -2.8069402 | AG68: =_xlfn.T.INV.2T(0.05,AE68) -> 1.9929971 | AH68: =AG68*AG68 -> 3.9720375 | AI68: =SQRT(AH68/(AE68+AH68)) -> 0.22716435 | AJ68: =-AI68 -> -0.22716435
A69: =A68+1 -> 44265 | B69: 64.45 | C69: 64.02 | D69: 65.03 | E69: 65.03 | F69: 66.08 | G69: 66.08 | H69: 63.81 | I69: 61.33 | J69: 59.7 | K69: 60.54 | L69: 60.54 | M69: 61.55 | N69: 61.55 | O69: 63.43 | P69: 63.21 | Q69: 61.66 | R69: 61.67 | S69: 61.67 | T69: 59.12 | U69: 59.12 | V69: 60.4 | W69: 61.09
A70: =A69+1 -> 44266 | B70: 66.02 | C70: 64.45 | D70: 64.02 | E70: 65.03 | F70: 65.03 | G70: 66.08 | H70: 66.08 | I70: 63.81 | J70: 61.33 | K70: 59.7 | L70: 60.54 | M70: 60.54 | N70: 61.55 | O70: 61.55 | P70: 63.43 | Q70: 63.21 | R70: 61.66 | S70: 61.67 | T70: 61.67 | U70: 59.12 | V70: 59.12 | W70: 60.4 | X70: 61.09
A71: =A70+1 -> 44267 | B71: 65.59 | C71: 66.02 | D71: 64.45 | E71: 64.02 | F71: 65.03 | G71: 65.03 | H71: 66.08 | I71: 66.08 | J71: 63.81 | K71: 61.33 | L71: 59.7 | M71: 60.54 | N71: 60.54 | O71: 61.55 | P71: 61.55 | Q71: 63.43 | R71: 63.21 | S71: 61.66 | T71: 61.67 | U71: 61.67 | V71: 59.12 | W71: 59.12 | X71: 60.4 | Y71: 61.09
A72: =A71+1 -> 44268 | B72: 65.59 | C72: 65.59 | D72: 66.02 | E72: 64.45 | F72: 64.02 | G72: 65.03 | H72: 65.03 | I72: 66.08 | J72: 66.08 | K72: 63.81 | L72: 61.33 | M72: 59.7 | N72: 60.54 | O72: 60.54 | P72: 61.55 | Q72: 61.55 | R72: 63.43 | S72: 63.21 | T72: 61.66 | U72: 61.67 | V72: 61.67 | W72: 59.12 | X72: 59.12 | Y72: 60.4 | Z72: 61.09
A73: =A72+1 -> 44269 | B73: 65.36 | C73: 65.59 | D73: 65.59 | E73: 66.02 | F73: 64.45 | G73: 64.02 | H73: 65.03 | I73: 65.03 | J73: 66.08 | K73: 66.08 | L73: 63.81 | M73: 61.33 | N73: 59.7 | O73: 60.54 | P73: 60.54 | Q73: 61.55 | R73: 61.55 | S73: 63.43 | T73: 63.21 | U73: 61.66 | V73: 61.67 | W73: 61.67 | X73: 59.12 | Y73: 59.12 | Z73: 60.4 | AA73: 61.09
A74: =A73+1 -> 44270 | B74: 65.36 | C74: 65.36 | D74: 65.59 | E74: 65.59 | F74: 66.02 | G74: 64.45 | H74: 64.02 | I74: 65.03 | J74: 65.03 | K74: 66.08 | L74: 66.08 | M74: 63.81 | N74: 61.33 | O74: 59.7 | P74: 60.54 | Q74: 60.54 | R74: 61.55 | S74: 61.55 | T74: 63.43 | U74: 63.21 | V74: 61.66 | W74: 61.67 | X74: 61.67 | Y74: 59.12 | Z74: 59.12 | AA74: 60.4
A75: =A74+1 -> 44271 | B75: 64.82 | C75: 65.36 | D75: 65.36 | E75: 65.59 | F75: 65.59 | G75: 66.02 | H75: 64.45 | I75: 64.02 | J75: 65.03 | K75: 65.03 | L75: 66.08 | M75: 66.08 | N75: 63.81 | O75: 61.33 | P75: 59.7 | Q75: 60.54 | R75: 60.54 | S75: 61.55 | T75: 61.55 | U75: 63.43 | V75: 63.21 | W75: 61.66 | X75: 61.67 | Y75: 61.67 | Z75: 59.12 | AA75: 59.12
A76: =A75+1 -> 44272 | B76: 64.55 | C76: 64.82 | D76: 65.36 | E76: 65.36 | F76: 65.59 | G76: 65.59 | H76: 66.02 | I76: 64.45 | J76: 64.02 | K76: 65.03 | L76: 65.03 | M76: 66.08 | N76: 66.08 | O76: 63.81 | P76: 61.33 | Q76: 59.7 | R76: 60.54 | S76: 60.54 | T76: 61.55 | U76: 61.55 | V76: 63.43 | W76: 63.21 | X76: 61.66 | Y76: 61.67 | Z76: 61.67 | AA76: 59.12
...

Sheet фильтрация
B1: таймер | D1: 3-точ скользящая | E1: 5-точ скользящая | F1: модель исх | G1: остатки | H1: e (t) - e(t-1) | I1: нижняя | J1: верхняя | K1: модель 3точ | L1: нижняя | M1: верхняя | N1: Экспоненц сглаживание | O1: 4-точечная | P1: 4-точечная_центрированная | Q1: модель | R1: нижняя | S1: верхняя
A2: 44244 | B2: 1 | C2: 61.09 | F2: =$V$3+$U$3*B2 -> 85.569446 | G2: =C2-F2 -> -24.479446 | I2: 85.569446 | J2: 85.569446 | N2: =C3 -> 60.4 | U2: исх модель | X2: 3-точ | AA2: 5-точ | AD2: 4-точ
A3: =A2+1 -> 44245 | B3: 2 | C3: 60.4 | D3: =AVERAGE(C2:C4) -> 60.203333 | F3: =$V$3+$U$3*B3 -> 85.559724 | G3: =C3-F3 -> -25.159724 | H3: =G3-G2 -> -0.68027803 | I3: 85.559724 | J3: 85.559724 | K3: =$Y$3+$X$3*B3 -> 85.608088 | L3: 85.608088 | M3: 85.608088 | N3: =0.3*C4 + 0.7*N2 -> 60.016 | U3: {=LINEST(C2:C1828,B2:B1828,1,1)} -> -0.0097219673 | V3: 85.579168 | X3: {=LINEST(D3:D1827,B3:B1827,1,1)} -> -0.009756976 | Y3: 85.627602 | AA3: {=LINEST(E4:E1826,B4:B1826,1,1)} -> -0.0097943839 | AB3: 85.678832 | AD3: {=LINEST(P4:P1826,B4:B1826,1,1)} -> -0.0097939876 | AE3: 85.678392
A4: =A3+1 -> 44246 | B4: 3 | C4: 59.12 | D4: =AVERAGE(C3:C5) -> 59.546667 | E4: =AVERAGE(C2:C6) -> 60.28 | F4: =$V$3+$U$3*B4 -> 85.550002 | G4: =C4-F4 -> -26.430002 | H4: =G4-G3 -> -1.270278 | I4: 85.550002 | J4: 85.550002 | K4: =$Y$3+$X$3*B4 -> 85.598331 | L4: 85.598331 | M4: 85.598331 | N4: =0.3*C5 + 0.7*N3 -> 59.7472 | O4: =AVERAGE(C2:C5) -> 59.9325 | P4: =AVERAGE(O4:O5) -> 60.005 | Q4: =$AE$3+$AD$3*B4 -> 85.64901 | R4: 85.64901 | S4: 85.64901 | U4: 0.0005215068 | V4: 0.55032106 | X4: 0.0005199454 | Y4: 0.54852343 | AA4: 0.00051872987 | AB4: 0.54709158 | AD4: 0.00051925526 | AE4: 0.5476457
A5: =A4+1 -> 44247 | B5: 4 | C5: 59.12 | D5: =AVERAGE(C4:C6) -> 59.97 | E5: =AVERAGE(C3:C7) -> 60.396 | F5: =$V$3+$U$3*B5 -> 85.54028 | G5: =C5-F5 -> -26.42028 | H5: =G5-G4 -> 0.0097219673 | I5: 85.54028 | J5: 85.54028 | K5: =$Y$3+$X$3*B5 -> 85.588574 | L5: 85.588574 | M5: 85.588574 | N5: =0.3*C6 + 0.7*N4 -> 60.32404 | O5: =AVERAGE(C3:C6) -> 60.0775 | P5: =AVERAGE(O5:O6) -> 60.23625 | Q5: =$AE$3+$AD$3*B5 -> 85.639216 | R5: 85.639216 | S5: 85.639216 | U5: 0.15996435 | V5: 11.756475 | X5: 0.16189291 | Y5: 11.702034 | AA5: 0.16372371 | AB5: 11.655491 | AD5: 0.16343562 | AE5: 11.667296
A6: =A5+1 -> 44248 | B6: 5 | C6: 61.67 | D6: =AVERAGE(C5:C7) -> 60.82 | E6: =AVERAGE(C4:C8) -> 60.648 | F6: =$V$3+$U$3*B6 -> 85.530558 | G6: =C6-F6 -> -23.860558 | H6: =G6-G5 -> 2.559722 | I6: 85.530558 | J6: 85.530558 | K6: =$Y$3+$X$3*B6 -> 85.578817 | L6: 85.578817 | M6: 85.578817 | N6: =0.3*C7 + 0.7*N5 -> 60.727828 | O6: =AVERAGE(C4:C7) -> 60.395 | P6: =AVERAGE(O6:O7) -> 60.7125 | Q6: =$AE$3+$AD$3*B6 -> 85.629422 | R6: 85.629422 | S6: 85.629422 | U6: 347.52685 | V6: 1825 | X6: 352.1397 | Y6: 1823 | AA6: 356.51002 | AB6: 1821 | AD6: 355.76014 | AE6: 1821
A7: =A6+1 -> 44249 | B7: 6 | C7: 61.67 | D7: =AVERAGE(C6:C8) -> 61.666667 | E7: =AVERAGE(C5:C9) -> 61.466 | F7: =$V$3+$U$3*B7 -> 85.520836 | G7: =C7-F7 -> -23.850836 | H7: =G7-G6 -> 0.0097219673 | I7: 85.520836 | J7: 85.520836 | K7: =$Y$3+$X$3*B7 -> 85.56906 | L7: 85.56906 | M7: 85.56906 | N7: =0.3*C8 + 0.7*N6 -> 61.00748 | O7: =AVERAGE(C5:C8) -> 61.03 | P7: =AVERAGE(O7:O8) -> 61.54125 | Q7: =$AE$3+$AD$3*B7 -> 85.619628 | R7: 85.619628 | S7: 85.619628 | U7: 48033.317 | V7: 252241.81 | X7: 48221.166 | Y7: 249637.25 | AA7: 48432.052 | AB7: 247383.7 | AD7: 48428.133 | AE7: 247885.08
A8: =A7+1 -> 44250 | B8: 7 | C8: 61.66 | D8: =AVERAGE(C7:C9) -> 62.18 | E8: =AVERAGE(C6:C10) -> 62.328 | F8: =$V$3+$U$3*B8 -> 85.511114 | G8: =C8-F8 -> -23.851114 | H8: =G8-G7 -> -0.00027803272 | I8: 85.511114 | J8: 85.511114 | K8: =$Y$3+$X$3*B8 -> 85.559303 | L8: 85.559303 | M8: 85.559303 | N8: =0.3*C9 + 0.7*N7 -> 61.668236 | O8: =AVERAGE(C6:C9) -> 62.0525 | P8: =AVERAGE(O8:O9) -> 62.2725 | Q8: =$AE$3+$AD$3*B8 -> 85.609834 | R8: 85.609834 | S8: 85.609834
A9: =A8+1 -> 44251 | B9: 8 | C9: 63.21 | D9: =AVERAGE(C8:C10) -> 62.766667 | E9: =AVERAGE(C7:C11) -> 62.304 | F9: =$V$3+$U$3*B9 -> 85.501392 | G9: =C9-F9 -> -22.291392 | H9: =G9-G8 -> 1.559722 | I9: 85.501392 | J9: 85.501392 | K9: =$Y$3+$X$3*B9 -> 85.549546 | L9: 85.549546 | M9: 85.549546 | N9: =0.3*C10 + 0.7*N8 -> 62.196765 | O9: =AVERAGE(C7:C10) -> 62.4925 | P9: =AVERAGE(O9:O10) -> 62.4775 | Q9: =$AE$3+$AD$3*B9 -> 85.60004 | R9: 85.60004 | S9: 85.60004 | U9: =U3-U4 -> -0.010243474 | V9: =V3-V4 -> 85.028847 | X9: =X3-X4 -> -0.010276921 | Y9: =Y3-Y4 -> 85.079079 | AA9: =AA3-AA4 -> -0.010313114 | AB9: =AB3-AB4 -> 85.13174 | AD9: =AD3-AD4 -> -0.010313243 | AE9: =AE3-AE4 -> 85.130746
A10: =A9+1 -> 44252 | B10: 9 | C10: 63.43 | D10: =AVERAGE(C9:C11) -> 62.73 | E10: =AVERAGE(C8:C12) -> 62.28 | F10: =$V$3+$U$3*B10 -> 85.49167 | G10: =C10-F10 -> -22.06167 | H10: =G10-G9 -> 0.22972197 | I10: 85.49167 | J10: 85.49167 | K10: =$Y$3+$X$3*B10 -> 85.539789 | L10: 85.539789 | M10: 85.539789 | N10: =0.3*C11 + 0.7*N9 -> 62.002736 | O10: =AVERAGE(C8:C11) -> 62.4625 | P10: =AVERAGE(O10:O11) -> 62.44875 | Q10: =$AE$3+$AD$3*B10 -> 85.590246 | R10: 85.590246 | S10: 85.590246
A11: =A10+1 -> 44253 | B11: 10 | C11: 61.55 | D11: =AVERAGE(C10:C12) -> 62.176667 | E11: =AVERAGE(C9:C13) -> 62.056 | F11: =$V$3+$U$3*B11 -> 85.481948 | G11: =C11-F11 -> -23.931948 | H11: =G11-G10 -> -1.870278 | I11: 85.481948 | J11: 85.481948 | K11: =$Y$3+$X$3*B11 -> 85.530032 | L11: 85.530032 | M11: 85.530032 | N11: =0.3*C12 + 0.7*N10 -> 61.866915 | O11: =AVERAGE(C9:C12) -> 62.435 | P11: =AVERAGE(O11:O12) -> 62.10125 | Q11: =$AE$3+$AD$3*B11 -> 85.580452 | R11: 85.580452 | S11: 85.580452
A12: =A11+1 -> 44254 | B12: 11 | C12: 61.55 | D12: =AVERAGE(C11:C13) -> 61.213333 | E12: =AVERAGE(C10:C14) -> 61.522 | F12: =$V$3+$U$3*B12 -> 85.472226 | G12: =C12-F12 -> -23.922226 | H12: =G12-G11 -> 0.0097219673 | I12: 85.472226 | J12: 85.472226 | K12: =$Y$3+$X$3*B12 -> 85.520275 | L12: 85.520275 | M12: 85.520275 | N12: =0.3*C13 + 0.7*N11 -> 61.46884 | O12: =AVERAGE(C10:C13) -> 61.7675 | P12: =AVERAGE(O12:O13) -> 61.40625 | Q12: =$AE$3+$AD$3*B12 -> 85.570658 | R12: 85.570658 | S12: 85.570658
A13: =A12+1 -> 44255 | B13: 12 | C13: 60.54 | D13: =AVERAGE(C12:C14) -> 60.876667 | E13: =AVERAGE(C11:C15) -> 60.776 | F13: =$V$3+$U$3*B13 -> 85.462504 | G13: =C13-F13 -> -24.922504 | H13: =G13-G12 -> -1.000278 | I13: 85.462504 | J13: 85.462504 | K13: =$Y$3+$X$3*B13 -> 85.510518 | L13: 85.510518 | M13: 85.510518 | N13: =0.3*C14 + 0.7*N12 -> 61.190188 | O13: =AVERAGE(C11:C14) -> 61.045 | P13: =AVERAGE(O13:O14) -> 60.81375 | Q13: =$AE$3+$AD$3*B13 -> 85.560864 | R13: 85.560864 | S13: 85.560864
A14: =A13+1 -> 44256 | B14: 13 | C14: 60.54 | D14: =AVERAGE(C13:C15) -> 60.26 | E14: =AVERAGE(C12:C16) -> 60.732 | F14: =$V$3+$U$3*B14 -> 85.452782 | G14: =C14-F14 -> -24.912782 | H14: =G14-G13 -> 0.0097219673 | I14: 85.452782 | J14: 85.452782 | K14: =$Y$3+$X$3*B14 -> 85.500761 | L14: 85.500761 | M14: 85.500761 | N14: =0.3*C15 + 0.7*N13 -> 60.743132 | O14: =AVERAGE(C12:C15) -> 60.5825 | P14: =AVERAGE(O14:O15) -> 60.555 | Q14: =$AE$3+$AD$3*B14 -> 85.55107 | R14: 85.55107 | S14: 85.55107
A15: =A14+1 -> 44257 | B15: 14 | C15: 59.7 | D15: =AVERAGE(C14:C16) -> 60.523333 | E15: =AVERAGE(C13:C17) -> 61.184 | F15: =$V$3+$U$3*B15 -> 85.44306 | G15: =C15-F15 -> -25.74306 | H15: =G15-G14 -> -0.83027803 | I15: 85.44306 | J15: 85.44306 | K15: =$Y$3+$X$3*B15 -> 85.491004 | L15: 85.491004 | M15: 85.491004 | N15: =0.3*C16 + 0.7*N14 -> 60.919192 | O15: =AVERAGE(C13:C16) -> 60.5275 | P15: =AVERAGE(O15:O16) -> 60.93625 | Q15: =$AE$3+$AD$3*B15 -> 85.541276 | R15: 85.541276 | S15: 85.541276
A16: =A15+1 -> 44258 | B16: 15 | C16: 61.33 | D16: =AVERAGE(C15:C17) -> 61.613333 | E16: =AVERAGE(C14:C18) -> 62.292 | F16: =$V$3+$U$3*B16 -> 85.433338 | G16: =C16-F16 -> -24.103338 | H16: =G16-G15 -> 1.639722 | I16: 85.433338 | J16: 85.433338 | K16: =$Y$3+$X$3*B16 -> 85.481247 | L16: 85.481247 | M16: 85.481247 | N16: =0.3*C17 + 0.7*N15 -> 61.786435 | O16: =AVERAGE(C14:C17) -> 61.345 | P16: =AVERAGE(O16:O17) -> 62.0375 | Q16: =$AE$3+$AD$3*B16 -> 85.531482 | R16: 85.531482 | S16: 85.531482
A17: =A16+1 -> 44259 | B17: 16 | C17: 63.81 | D17: =AVERAGE(C16:C18) -> 63.74 | E17: =AVERAGE(C15:C19) -> 63.4 | F17: =$V$3+$U$3*B17 -> 85.423616 | G17: =C17-F17 -> -21.613616 | H17: =G17-G16 -> 2.489722 | I17: 85.423616 | J17: 85.423616 | K17: =$Y$3+$X$3*B17 -> 85.47149 | L17: 85.47149 | M17: 85.47149 | N17: =0.3*C18 + 0.7*N16 -> 63.074504 | O17: =AVERAGE(C15:C18) -> 62.73 | P17: =AVERAGE(O17:O18) -> 63.5275 | Q17: =$AE$3+$AD$3*B17 -> 85.521688 | R17: 85.521688 | S17: 85.521688
A18: =A17+1 -> 44260 | B18: 17 | C18: 66.08 | D18: =AVERAGE(C17:C19) -> 65.323333 | E18: =AVERAGE(C16:C20) -> 64.466 | F18: =$V$3+$U$3*B18 -> 85.413894 | G18: =C18-F18 -> -19.333894 | H18: =G18-G17 -> 2.279722 | I18: 85.413894 | J18: 85.413894 | K18: =$Y$3+$X$3*B18 -> 85.461733 | L18: 85.461733 | M18: 85.461733 | N18: =0.3*C19 + 0.7*N17 -> 63.976153 | O18: =AVERAGE(C16:C19) -> 64.325 | P18: =AVERAGE(O18:O19) -> 64.7875 | Q18: =$AE$3+$AD$3*B18 -> 85.511894 | R18: 85.511894 | S18: 85.511894
A19: =A18+1 -> 44261 | B19: 18 | C19: 66.08 | D19: =AVERAGE(C18:C20) -> 65.73 | E19: =AVERAGE(C17:C21) -> 65.206 | F19: =$V$3+$U$3*B19 -> 85.404172 | G19: =C19-F19 -> -19.324172 | H19: =G19-G18 -> 0.0097219673 | I19: 85.404172 | J19: 85.404172 | K19: =$Y$3+$X$3*B19 -> 85.451977 | L19: 85.451977 | M19: 85.451977 | N19: =0.3*C20 + 0.7*N18 -> 64.292307 | O19: =AVERAGE(C17:C20) -> 65.25 | P19: =AVERAGE(O19:O20) -> 65.4025 | Q19: =$AE$3+$AD$3*B19 -> 85.5021 | R19: 85.5021 | S19: 85.5021
A20: =A19+1 -> 44262 | B20: 19 | C20: 65.03 | D20: =AVERAGE(C19:C21) -> 65.38 | E20: =AVERAGE(C18:C22) -> 65.248 | F20: =$V$3+$U$3*B20 -> 85.39445 | G20: =C20-F20 -> -20.36445 | H20: =G20-G19 -> -1.040278 | I20: 85.39445 | J20: 85.39445 | K20: =$Y$3+$X$3*B20 -> 85.44222 | L20: 85.44222 | M20: 85.44222 | N20: =0.3*C21 + 0.7*N19 -> 64.513615 | O20: =AVERAGE(C18:C21) -> 65.555 | P20: =AVERAGE(O20:O21) -> 65.2975 | Q20: =$AE$3+$AD$3*B20 -> 85.492306 | R20: 85.492306 | S20: 85.492306
A21: =A20+1 -> 44263 | B21: 20 | C21: 65.03 | D21: =AVERAGE(C20:C22) -> 64.693333 | E21: =AVERAGE(C19:C23) -> 64.922 | F21: =$V$3+$U$3*B21 -> 85.384728 | G21: =C21-F21 -> -20.354728 | H21: =G21-G20 -> 0.0097219673 | I21: 85.384728 | J21: 85.384728 | K21: =$Y$3+$X$3*B21 -> 85.432463 | L21: 85.432463 | M21: 85.432463 | N21: =0.3*C22 + 0.7*N20 -> 64.36553 | O21: =AVERAGE(C19:C22) -> 65.04 | P21: =AVERAGE(O21:O22) -> 64.83625 | Q21: =$AE$3+$AD$3*B21 -> 85.482512 | R21: 85.482512 | S21: 85.482512
... A70: =A69+1 -> 44312 | B70: 69 | C70: 62.02 | D70: =AVERAGE(C69:C71) -> 62.356667 | E70: =AVERAGE(C68:C72) -> 62.612 | F70: =$V$3+$U$3*B70 -> 84.908352 | G70: =C70-F70 -> -22.888352 | H70: =G70-G69 -> 0.0097219673 | I70: 84.908352 | J70: 84.908352 | K70: =$Y$3+$X$3*B70 -> 84.954371 | L70: 84.954371 | M70: 84.954371 | N70: =0.3*C71 + 0.7*N69 -> 62.361649 | O70: =AVERAGE(C68:C71) -> 62.3125 | P70: =AVERAGE(O70:O71) -> 62.51625 | Q70: =$AE$3+$AD$3*B70 -> 85.002607 | R70: 85.002607 | S70: 85.002607
A71: =A70+1 -> 44313 | B71: 70 | C71: 63.03 | D71: =AVERAGE(C70:C72) -> 62.953333 | E71: =AVERAGE(C69:C73) -> 63.176 | F71: =$V$3+$U$3*B71 -> 84.89863 | G71: =C71-F71 -> -21.86863 | H71: =G71-G70 -> 1.019722 | I71: 84.89863 | J71: 84.89863 | K71: =$Y$3+$X$3*B71 -> 84.944614 | L71: 84.944614 | M71: 84.944614 | N71: =0.3*C72 + 0.7*N70 -> 62.796154 | O71: =AVERAGE(C69:C72) -> 62.72 | P71: =AVERAGE(O71:O72) -> 63.0925 | Q71: =$AE$3+$AD$3*B71 -> 84.992813 | R71: 84.992813 | S71: 84.992813 | AF71: СРЕДНЕЕ качество (R² = 43%)
A72: =A71+1 -> 44314 | B72: 71 | C72: 63.81 | D72: =AVERAGE(C71:C73) -> 63.946667 | E72: =AVERAGE(C70:C74) -> 63.472 | F72: =$V$3+$U$3*B72 -> 84.888908 | G72: =C72-F72 -> -21.078908 | H72: =G72-G71 -> 0.78972197 | I72: 84.888908 | J72: 84.888908 | K72: =$Y$3+$X$3*B72 -> 84.934857 | L72: 84.934857 | M72: 84.934857 | N72: =0.3*C73 + 0.7*N71 -> 63.457308 | O72: =AVERAGE(C70:C73) -> 63.465 | P72: =AVERAGE(O72:O73) -> 63.65 | Q72: =$AE$3+$AD$3*B72 -> 84.983019 | R72: 84.983019 | S72: 84.983019 | AF72: Показывает нелинейность тренда
A73: =A72+1 -> 44315 | B73: 72 | C73: 65 | D73: =AVERAGE(C72:C74) -> 64.103333 | E73: =AVERAGE(C71:C75) -> 63.768 | F73: =$V$3+$U$3*B73 -> 84.879186 | G73: =C73-F73 -> -19.879186 | H73: =G73-G72 -> 1.199722 | I73: 84.879186 | J73: 84.879186 | K73: =$Y$3+$X$3*B73 -> 84.9251 | L73: 84.9251 | M73: 84.9251 | N73: =0.3*C74 + 0.7*N72 -> 63.470115 | O73: =AVERAGE(C71:C74) -> 63.835 | P73: =AVERAGE(O73:O74) -> 63.89375 | Q73: =$AE$3+$AD$3*B73 -> 84.973225 | R73: 84.973225 | S73: 84.973225 | AF73: Есть изгибы (рост-падение-рост)
A74: =A73+1 -> 44316 | B74: 73 | C74: 63.5 | D74: =AVERAGE(C73:C75) -> 64 | E74: =AVERAGE(C72:C76) -> 64.054 | F74: =$V$3+$U$3*B74 -> 84.869464 | G74: =C74-F74 -> -21.369464 | H74: =G74-G73 -> -1.490278 | I74: 84.869464 | J74: 84.869464 | K74: =$Y$3+$X$3*B74 -> 84.915343 | L74: 84.915343 | M74: 84.915343 | N74: =0.3*C75 + 0.7*N73 -> 63.479081 | O74: =AVERAGE(C72:C75) -> 63.9525 | P74: =AVERAGE(O74:O75) -> 64.03375 | Q74: =$AE$3+$AD$3*B74 -> 84.963431 | R74: 84.963431 | S74: 84.963431 | AF74: ЛУЧШЕ всего описывает данные
A75: =A74+1 -> 44317 | B75: 74 | C75: 63.5 | D75: =AVERAGE(C74:C76) -> 63.82 | E75: =AVERAGE(C73:C77) -> 64.184 | F75: =$V$3+$U$3*B75 -> 84.859742 | G75: =C75-F75 -> -21.359742 | H75: =G75-G74 -> 0.0097219673 | I75: 84.859742 | J75: 84.859742 | K75: =$Y$3+$X$3*B75 -> 84.905586 | L75: 84.905586 | M75: 84.905586 | N75: =0.3*C76 + 0.7*N74 -> 63.773357 | O75: =AVERAGE(C73:C76) -> 64.115 | P75: =AVERAGE(O75:O76) -> 64.0475 | Q75: =$AE$3+$AD$3*B75 -> 84.953637 | R75: 84.953637 | S75: 84.953637
A76: =A75+1 -> 44318 | B76: 75 | C76: 64.46 | D76: =AVERAGE(C75:C77) -> 64.14 | E76: =AVERAGE(C74:C78) -> 64.328 | F76: =$V$3+$U$3*B76 -> 84.85002 | G76: =C76-F76 -> -20.39002 | H76: =G76-G75 -> 0.96972197 | I76: 84.85002 | J76: 84.85002 | K76: =$Y$3+$X$3*B76 -> 84.895829 | L76: 84.895829 | M76: 84.895829 | N76: =0.3*C77 + 0.7*N75 -> 63.97935 | O76: =AVERAGE(C74:C77) -> 63.98 | P76: =AVERAGE(O76:O77) -> 64.2575 | Q76: =$AE$3+$AD$3*B76 -> 84.943843 | R76: 84.943843 | S76: 84.943843
A77: =A76+1 -> 44319 | B77: 76 | C77: 64.46 | D77: =AVERAGE(C76:C78) -> 64.88 | E77: =AVERAGE(C75:C79) -> 64.754 | F77: =$V$3+$U$3*B77 -> 84.840298 | G77: =C77-F77 -> -20.380298 | H77: =G77-G76 -> 0.0097219673 | I77: 84.840298 | J77: 84.840298 | K77: =$Y$3+$X$3*B77 -> 84.886072 | L77: 84.886072 | M77: 84.886072 | N77: =0.3*C78 + 0.7*N76 -> 64.501545 | O77: =AVERAGE(C75:C78) -> 64.535 | P77: =AVERAGE(O77:O78) -> 64.80125 | Q77: =$AE$3+$AD$3*B77 -> 84.934049 | R77: 84.934049 | S77: 84.934049
A78: =A77+1 -> 44320 | B78: 77 | C78: 65.72 | D78: =AVERAGE(C77:C79) -> 65.27 | E78: =AVERAGE(C76:C80) -> 65 | F78: =$V$3+$U$3*B78 -> 84.830576 | G78: =C78-F78 -> -19.110576 | H78: =G78-G77 -> 1.269722 | I78: 84.830576 | J78: 84.830576 | K78: =$Y$3+$X$3*B78 -> 84.876315 | L78: 84.876315 | M78: 84.876315 | N78: =0.3*C79 + 0.7*N77 -> 64.840081 | O78: =AVERAGE(C76:C79) -> 65.0675 | P78: =AVERAGE(O78:O79) -> 65.10125 | Q78: =$AE$3+$AD$3*B78 -> 84.924255 | R78: 84.924255 | S78: 84.924255
A79: =A78+1 -> 44321 | B79: 78 | C79: 65.63 | D79: =AVERAGE(C78:C80) -> 65.36 | E79: =AVERAGE(C77:C81) -> 65.1 | F79: =$V$3+$U$3*B79 -> 84.820854 | G79: =C79-F79 -> -19.190854 | H79: =G79-G78 -> -0.080278033 | I79: 84.820854 | J79: 84.820854 | K79: =$Y$3+$X$3*B79 -> 84.866558 | L79: 84.866558 | M79: 84.866558 | N79: =0.3*C80 + 0.7*N78 -> 64.807057 | O79: =AVERAGE(C77:C80) -> 65.135 | P79: =AVERAGE(O79:O80) -> 65.1975 | Q79: =$AE$3+$AD$3*B79 -> 84.914461 | R79: 84.914461 | S79: 84.914461
A80: =A79+1 -> 44322 | B80: 79 | C80: 64.73 | D80: =AVERAGE(C79:C81) -> 65.106667 | E80: =AVERAGE(C78:C82) -> 65.2 | F80: =$V$3+$U$3*B80 -> 84.811132 | G80: =C80-F80 -> -20.081132 | H80: =G80-G79 -> -0.89027803 | I80: 84.811132 | J80: 84.811132 | K80: =$Y$3+$X$3*B80 -> 84.856801 | L80: 84.856801 | M80: 84.856801 | N80: =0.3*C81 + 0.7*N79 -> 64.85294 | O80: =AVERAGE(C78:C81) -> 65.26 | P80: =AVERAGE(O80:O81) -> 65.165 | Q80: =$AE$3+$AD$3*B80 -> 84.904667 | R80: 84.904667 | S80: 84.904667
A81: =A80+1 -> 44323 | B81: 80 | C81: 64.96 | D81: =AVERAGE(C80:C82) -> 64.883333 | E81: =AVERAGE(C79:C83) -> 65.04 | F81: =$V$3+$U$3*B81 -> 84.80141 | G81: =C81-F81 -> -19.84141 | H81: =G81-G80 -> 0.23972197 | I81: 84.80141 | J81: 84.80141 | K81: =$Y$3+$X$3*B81 -> 84.847044 | L81: 84.847044 | M81: 84.847044 | N81: =0.3*C82 + 0.7*N80 -> 64.885058 | O81: =AVERAGE(C79:C82) -> 65.07 | P81: =AVERAGE(O81:O82) -> 64.98125 | Q81: =$AE$3+$AD$3*B81 -> 84.894873 | R81: 84.894873 | S81: 84.894873
A82: =A81+1 -> 44324 | B82: 81 | C82: 64.96 | D82: =AVERAGE(C81:C83) -> 64.946667 | E82: =AVERAGE(C80:C84) -> 64.898 | F82: =$V$3+$U$3*B82 -> 84.791688 | G82: =C82-F82 -> -19.831688 | H82: =G82-G81 -> 0.0097219673 | I82: 84.791688 | J82: 84.791688 | K82: =$Y$3+$X$3*B82 -> 84.837287 | L82: 84.837287 | M82: 84.837287 | N82: =0.3*C83 + 0.7*N81 -> 64.895541 | O82: =AVERAGE(C80:C83) -> 64.8925 | P82: =AVERAGE(O82:O83) -> 64.91625 | Q82: =$AE$3+$AD$3*B82 -> 84.885079 | R82: 84.885079 | S82: 84.885079
A83: =A82+1 -> 44325 | B83: 82 | C83: 64.92 | D83: =AVERAGE(C82:C84) -> 64.933333 | E83: =AVERAGE(C81:C85) -> 65.014 | F83: =$V$3+$U$3*B83 -> 84.781966 | G83: =C83-F83 -> -19.861966 | H83: =G83-G82 -> -0.030278033 | I83: 84.781966 | J83: 84.781966 | K83: =$Y$3+$X$3*B83 -> 84.82753 | L83: 84.82753 | M83: 84.82753 | N83: =0.3*C84 + 0.7*N82 -> 64.902878 | O83: =AVERAGE(C81:C84) -> 64.94 | P83: =AVERAGE(O83:O84) -> 64.98375 | Q83: =$AE$3+$AD$3*B83 -> 84.875285 | R83: 84.875285 | S83: 84.875285
A84: =A83+1 -> 44326 | B84: 83 | C84: 64.92 | D84: =AVERAGE(C83:C85) -> 65.05 | E84: =AVERAGE(C82:C86) -> 65.214 | F84: =$V$3+$U$3*B84 -> 84.772244 | G84: =C84-F84 -> -19.852244 | H84: =G84-G83 -> 0.0097219673 | I84: 84.772244 | J84: 84.772244 | K84: =$Y$3+$X$3*B84 -> 84.817773 | L84: 84.817773 | M84: 84.817773 | N84: =0.3*C85 + 0.7*N83 -> 65.025015 | O84: =AVERAGE(C82:C85) -> 65.0275 | P84: =AVERAGE(O84:O85) -> 65.1525 | Q84: =$AE$3+$AD$3*B84 -> 84.865491 | R84: 84.865491 | S84: 84.865491
A85: =A84+1 -> 44327 | B85: 84 | C85: 65.31 | D85: =AVERAGE(C84:C86) -> 65.396667 | E85: =AVERAGE(C83:C87) -> 64.986 | F85: =$V$3+$U$3*B85 -> 84.762522 | G85: =C85-F85 -> -19.452522 | H85: =G85-G84 -> 0.39972197 | I85: 84.762522 | J85: 84.762522 | K85: =$Y$3+$X$3*B85 -> 84.808016 | L85: 84.808016 | M85: 84.808016 | N85: =0.3*C86 + 0.7*N84 -> 65.30551 | O85: =AVERAGE(C83:C86) -> 65.2775 | P85: =AVERAGE(O85:O86) -> 65.14 | Q85: =$AE$3+$AD$3*B85 -> 84.855697 | R85: 84.855697 | S85: 84.855697
A86: =A85+1 -> 44328 | B86: 85 | C86: 65.96 | D86: =AVERAGE(C85:C87) -> 65.03 | E86: =AVERAGE(C84:C88) -> 65.066 | F86: =$V$3+$U$3*B86 -> 84.7528 | G86: =C86-F86 -> -18.7928 | H86: =G86-G85 -> 0.65972197 | I86: 84.7528 | J86: 84.7528 | K86: =$Y$3+$X$3*B86 -> 84.798259 | L86: 84.798259 | M86: 84.798259 | N86: =0.3*C87 + 0.7*N85 -> 64.859857 | O86: =AVERAGE(C84:C87) -> 65.0025 | P86: =AVERAGE(O86:O87) -> 65.0525 | Q86: =$AE$3+$AD$3*B86 -> 84.845903 | R86: 84.845903 | S86: 84.845903
... A1826: =A1825+1 -> 46068 | B1826: 1825 | C1826: 62.53 | D1826: =AVERAGE(C1825:C1827) -> 62.703333 | E1826: =AVERAGE(C1824:C1828) -> 62.738 | F1826: =$V$3+$U$3*B1826 -> 67.836577 | G1826: =C1826-F1826 -> -5.3065774 | H1826: =G1826-G1825 -> -0.51027803 | I1826: 67.836577 | J1826: 67.836577 | K1826: =$Y$3+$X$3*B1826 -> 67.821121 | L1826: 67.821121 | M1826: 67.821121 | N1826: =0.3*C1827 + 0.7*N1825 -> 62.993343 | O1826: =AVERAGE(C1824:C1827) -> 62.79 | P1826: =AVERAGE(O1826:O1827) -> 62.725 | Q1826: =$AE$3+$AD$3*B1826 -> 67.804365 | R1826: 67.804365 | S1826: 67.804365
A1827: =A1826+1 -> 46069 | B1827: 1826 | C1827: 62.53 | D1827: =AVERAGE(C1826:C1828) -> 62.53 | F1827: =$V$3+$U$3*B1827 -> 67.826855 | G1827: =C1827-F1827 -> -5.2968554 | H1827: =G1827-G1826 -> 0.0097219673 | I1827: 67.826855 | J1827: 67.826855 | K1827: =$Y$3+$X$3*B1827 -> 67.811364 | L1827: 67.811364 | M1827: 67.811364 | N1827: =0.3*C1828 + 0.7*N1826 -> 62.85434 | O1827: =AVERAGE(C1825:C1828) -> 62.66 | Q1827: =$AE$3+$AD$3*B1827 -> 67.794571 | R1827: 67.794571 | S1827: 67.794571
...

Sheet c 1200
A1: дата | B1: DCOILWTICO | D1: сглаживание: | E1: дата | F1: таймер | G1: DCOILWTICO | H1: модель исх | I1: остатки | J1: e (t) - e(t-1) | K1: нижняя | L1: верхняя | M1: 3-точ | N1: модель3-точ | O1: нижняя | P1: верхняя | Q1: 4-точ | R1: 4-точ цент | S1: модель 4-точ | T1: нижняя | U1: верхняя | V1: 5-точ
A2: 45443 | B2: 77.97 | E2: 45443 | F2: 1 | G2: 77.97 | H2: =$AF$6+$AE$6*F2 -> 78.399704 | I2: =G2-H2 -> -0.42970426 | K2: 78.399704 | L2: 78.399704
A3: 45444 | B3: 77.97 | E3: 45444 | F3: 2 | G3: 77.97 | H3: =$AF$6+$AE$6*F3 -> 78.367192 | I3: =G3-H3 -> -0.39719233 | J3: =I3-I2 -> 0.032511933 | K3: 78.367192 | L3: 78.367192 | M3: =AVERAGE(G2:G4) -> 77.066667 | N3: =$AI$6+$AH$6*F3 -> 78.384285 | O3: 78.384285 | P3: 78.384285 | AD3: модели для расчетов
A4: 45445 | B4: 75.26 | E4: 45445 | F4: 3 | G4: 75.26 | H4: =$AF$6+$AE$6*F4 -> 78.33468 | I4: =G4-H4 -> -3.0746804 | J4: =I4-I3 -> -2.6774881 | K4: 78.33468 | L4: 78.33468 | M4: =AVERAGE(G3:G5) -> 76.163333 | N4: =$AI$6+$AH$6*F4 -> 78.351698 | O4: 78.351698 | P4: 78.351698 | Q4: =AVERAGE(G2:G5) -> 76.615 | R4: =AVERAGE(Q4:Q5) -> 76.1525 | S4: =$AL$6+$AK$6*F4 -> 78.377618 | T4: 78.377618 | U4: 78.377618 | AE4: исходная | AH4: 3-точ | AK4: 4-точ
A5: 45446 | B5: 75.26 | E5: 45446 | F5: 4 | G5: 75.26 | H5: =$AF$6+$AE$6*F5 -> 78.302168 | I5: =G5-H5 -> -3.0421685 | J5: =I5-I4 -> 0.032511933 | K5: 78.302168 | L5: 78.302168 | M5: =AVERAGE(G4:G6) -> 74.93 | N5: =$AI$6+$AH$6*F5 -> 78.31911 | O5: 78.31911 | P5: 78.31911 | Q5: =AVERAGE(G3:G6) -> 75.69 | R5: =AVERAGE(Q5:Q6) -> 75.32875 | S5: =$AL$6+$AK$6*F5 -> 78.344933 | T5: 78.344933 | U5: 78.344933
A6: 45447 | B6: 74.27 | E6: 45447 | F6: 5 | G6: 74.27 | H6: =$AF$6+$AE$6*F6 -> 78.269657 | I6: =G6-H6 -> -3.9996565 | J6: =I6-I5 -> -0.95748807 | K6: 78.269657 | L6: 78.269657 | M6: =AVERAGE(G5:G7) -> 74.87 | N6: =$AI$6+$AH$6*F6 -> 78.286523 | O6: 78.286523 | P6: 78.286523 | Q6: =AVERAGE(G4:G7) -> 74.9675 | R6: =AVERAGE(Q6:Q7) -> 75.125 | S6: =$AL$6+$AK$6*F6 -> 78.312248 | T6: 78.312248 | U6: 78.312248 | V6: =AVERAGE(G2:G6) -> 76.146 | AE6: {=LINEST(G2:G629,F2:F629,1,1)} -> -0.032511933 | AF6: 78.432216 | AH6: {=LINEST(M3:M628,F3:F628,1,1)} -> -0.032587514 | AI6: 78.44946 | AK6: {=LINEST(R4:R627,F4:F627,1,1)} -> -0.032685176 | AL6: 78.475674
A7: 45448 | B7: 75.08 | E7: 45448 | F7: 6 | G7: 75.08 | H7: =$AF$6+$AE$6*F7 -> 78.237145 | I7: =G7-H7 -> -3.1571446 | J7: =I7-I6 -> 0.84251193 | K7: 78.237145 | L7: 78.237145 | M7: =AVERAGE(G6:G8) -> 75.29 | N7: =$AI$6+$AH$6*F7 -> 78.253935 | O7: 78.253935 | P7: 78.253935 | Q7: =AVERAGE(G5:G8) -> 75.2825 | R7: =AVERAGE(Q7:Q8) -> 75.44125 | S7: =$AL$6+$AK$6*F7 -> 78.279563 | T7: 78.279563 | U7: 78.279563 | V7: =AVERAGE(G3:G7) -> 75.568 | AE7: 0.00079663011 | AF7: 0.28918386 | AH7: 0.00078310733 | AI7: 0.28404945 | AK7: 0.00077741449 | AL7: 0.28176119
A8: 45449 | B8: 76.52 | E8: 45449 | F8: 7 | G8: 76.52 | H8: =$AF$6+$AE$6*F8 -> 78.204633 | I8: =G8-H8 -> -1.6846327 | J8: =I8-I7 -> 1.4725119 | K8: 78.204633 | L8: 78.204633 | M8: =AVERAGE(G7:G9) -> 76.043333 | N8: =$AI$6+$AH$6*F8 -> 78.221348 | O8: 78.221348 | P8: 78.221348 | Q8: =AVERAGE(G6:G9) -> 75.6 | R8: =AVERAGE(Q8:Q9) -> 75.8825 | S8: =$AL$6+$AK$6*F8 -> 78.246878 | T8: 78.246878 | U8: 78.246878 | V8: =AVERAGE(G4:G8) -> 75.278 | AE8: 0.72682907 | AF8: 3.6191369 | AH8: 0.73510486 | AI8: 3.5407202 | AK8: 0.73971089 | AL8: 3.4981492
A9: 45450 | B9: 76.53 | E9: 45450 | F9: 8 | G9: 76.53 | H9: =$AF$6+$AE$6*F9 -> 78.172121 | I9: =G9-H9 -> -1.6421207 | J9: =I9-I8 -> 0.042511933 | K9: 78.172121 | L9: 78.172121 | M9: =AVERAGE(G8:G10) -> 76.526667 | N9: =$AI$6+$AH$6*F9 -> 78.18876 | O9: 78.18876 | P9: 78.18876 | Q9: =AVERAGE(G7:G10) -> 76.165 | R9: =AVERAGE(Q9:Q10) -> 76.62375 | S9: =$AL$6+$AK$6*F9 -> 78.214192 | T9: 78.214192 | U9: 78.214192 | V9: =AVERAGE(G5:G9) -> 75.532 | AE9: 1665.6055 | AF9: 626 | AH9: 1731.6491 | AI9: 624 | AK9: 1767.6505 | AL9: 622
A10: 45451 | B10: 76.53 | E10: 45451 | F10: 9 | G10: 76.53 | H10: =$AF$6+$AE$6*F10 -> 78.139609 | I10: =G10-H10 -> -1.6096088 | J10: =I10-I9 -> 0.032511933 | K10: 78.139609 | L10: 78.139609 | M10: =AVERAGE(G9:G11) -> 77.27 | N10: =$AI$6+$AH$6*F10 -> 78.156173 | O10: 78.156173 | P10: 78.156173 | Q10: =AVERAGE(G8:G11) -> 77.0825 | R10: =AVERAGE(Q10:Q11) -> 77.36125 | S10: =$AL$6+$AK$6*F10 -> 78.181507 | T10: 78.181507 | U10: 78.181507 | V10: =AVERAGE(G6:G10) -> 75.786 | AE10: 21816.353 | AF10: 8199.443 | AH10: 21709.165 | AI10: 7822.9007 | AK10: 21630.824 | AL10: 7611.4439
A11: 45452 | B11: 78.75 | E11: 45452 | F11: 10 | G11: 78.75 | H11: =$AF$6+$AE$6*F11 -> 78.107097 | I11: =G11-H11 -> 0.64290313 | J11: =I11-I10 -> 2.2525119 | K11: 78.107097 | L11: 78.107097 | M11: =AVERAGE(G10:G12) -> 78.01 | N11: =$AI$6+$AH$6*F11 -> 78.123585 | O11: 78.123585 | P11: 78.123585 | Q11: =AVERAGE(G9:G12) -> 77.64 | R11: =AVERAGE(Q11:Q12) -> 77.93375 | S11: =$AL$6+$AK$6*F11 -> 78.148822 | T11: 78.148822 | U11: 78.148822 | V11: =AVERAGE(G7:G11) -> 76.682
